Workbook

Sheet Проблеми
A1: Знахідки в даних і рішення (дамп від 30.09.2026)
A3: № | B3: Пріоритет | C3: Що знайдено | D3: Скільки / де | E3: Що зробити | F3: Рішення
A4: 1 | B4: Високий | C4: Аудиторія береться від викладача, а кілька викладачів мають одну: у той самий слот різні групи «сидять» в одній аудиторії. | D4: 80 збігів в аудиторіях: 203, 301, 308, 426. Список на аркуші «Збіги аудиторій». | E4: Вирішувати вручну (поле аудиторії в занятті). | F4: Вручну пізніше. Генератор аудиторії не враховує.
A5: 2 | B5: Високий | C5: Предмет «Фізична культура» неактивний, але стоїть в активних заняттях. Паралельно є активний «Фізичне виховання». | D5: «Фізична культура» (id 78): 36 занять у групах 87–98. «Фізичне виховання» (id 79): 27 занять у групах 75–86 і 99. | E5: Перенести заняття з id 78 на id 79, видалити предмет 78. | F5: Один предмет. Залишити «Фізичне виховання».
A6: 3 | B6: Високий | C6: Викладач-заглушка «ДТЕФК !.!.» у «Захисті України»: це зовнішній блок, а не викладач. | D6: Групи 87, 89, 90, 91: понеділок, усі 4 пари, лише чисельник. | E6: У генераторі закріплений блок без викладача. У довіднику позначити як «зовнішній». | F6: Блок раз на два тижні для груп 2 курсу.
A7: 4 | B7: Середній | C7: Один куратор веде виховну годину у двох груп в один слот (чт, 4 пара). | D7: Гончаров О.М.: групи 86 і 93. | E7: Закласти як потік: однакові викладач, предмет і слот дозволені. | F7: Так, спільна виховна година.
A8: 5 | B8: Середній | C8: settings.semester_start = 2025-09-01 (торішня дата). Парність працює, бо між 01.09.2025 і 31.08.2026 рівно 52 тижні. | D8: Поточне значення: 2025-09-01. | E8: Змінити на 2026-08-31 (понеділок). Парність не зміниться: 1-й тиждень графіка = чисельник.
A9: 6 | B9: Середній | C9: Найбільш завантажені викладачі майже повністю заповнюють свої слоти: це найжорсткіші обмеження для генератора. | D9: Сесь О.В., Домніна Г.С.: 17 з 20 слотів (85%); ще 7 викладачів по 15–16 слотів. Див. аркуш «Викладачі». | E9: Додати в генератор попередню перевірку виконуваності.
A10: 7 | B10: Середній | C10: У чисельнику і знаменнику один слот часто зайнятий різними предметами (чергування). | D10: 65 слотів із різними предметами по тижнях, ще 12 слотів зайняті лише в одному тижні. | E10: Генератор працює з двома тижнями окремо.
A11: 8 | B11: Середній | C11: Другий викладач у ту саму пару: поділ групи на підгрупи. | D11: 22 заняття: «Іноземна мова (за професійним спрямуванням)» (12) і «Технології (Модуль 2 „Креслення”)» (10). | E11: У моделі навантаження потрібна ознака «підгрупи». | F11: Так, це підгрупи.
A12: 9 | B12: Середній | C12: Комп’ютерна електроніка, група 85: у розкладі 3 пари в чисельнику і 2 у знаменнику = 43 пари = 86 год, за планом 84 год (2 + 3). | D12: Група 85. Комп’ютерна схемотехніка збігається з планом (2 + 3). Інші 6 предметів теж збігаються. | E12: Вирішити політику: рівно за годинами плану чи допустима +1 пара для вирівнювання тижнів (зараз 17 і 17 пар).
A13: 10 | B13: Середній | C13: Група 88 (2 курс, ЕА-25-1/9-88) без «Захисту України», хоча в інших 4 групах 2 курсу блок є. | D13: Понеділок чисельника в неї звичайний (пари 2–4). | E13: Перевірити, чи це так і має бути, чи блок не внесено.
A14: 11 | B14: Низький | C14: Рядки «дробл. лаб. раб.» в аркуші навантаження мають 0 год/тиж і без викладача. | D14: Група 85: комп’ютерна електроніка 20 год, схемотехніка 40 год, WEB-дизайн 40 год. | E14: Припущення: це додаткові години на поділ лабораторних, окремих пар для групи вони не дають. Підтвердити.
A15: 12 | B15: Низький | C15: faculty_id груп у БД не збігається з відділеннями в QuickRaport. | D15: Збігається лише КІ (15). Групи РЗ і ІТ розкидані по faculty 12 і 13. | E15: Для планів навантаження використовувати шифр (спеціальність + рік вступу), а не faculty_id.
A16: 13 | B16: Низький | C16: Варіанти назв предметів, схожі на дублікати. | D16: «Інформатика» (10) і «Інформатика*» (5); «Економіка…» у трьох варіантах (13 / 4 / 8); «Основи національного с» обрізано (1 заняття). | E16: Перевірити, чи це різні предмети за планом. | F16: Не критично.
A17: 14 | B17: Низький | C17: Тестові дані в довідниках. | D17: Неактивні предмети: Programming, Databases, Web Technologies, Mathematics, Project Management. Неактивні викладачі: Olena Kovalenko, Ivan Petrenko, Maria Shevchenko, Andrii Bondar, Iryna Melnyk. | E17: Видалити: жоден з них не використовується в заняттях.
A18: 15 | B18: Низький | C18: Видалені (неактивні) заняття лишилися в таблиці. | D18: 6 занять: групи 75, 77, 84, 85, 87. | E18: Можна видалити остаточно.
A19: 16 | B19: Низький | C19: Немає аудиторії у викладачів, які ведуть заняття. | D19: Веклич А.В. (1 пара на тиждень), ДТЕФК !.!. | E19: Вказати аудиторію або задавати вручну в занятті. | F19: Вручну.
A20: 17 | B20: Інфо | C20: Конфліктів у поточному розкладі немає: жодна група і жоден викладач не мають двох різних занять в один слот. | D20: 0 конфліктів груп, 0 конфліктів викладачів (потоки й спільні слоти не рахуються). | E20: Поточний розклад можна взяти як еталон для перевірки генератора.
A21: 18 | B21: Інфо | C21: Виховна година є у всіх 25 груп: чт, 4 пара, щотижня, викладач = куратор групи. Інших занять у чт на 4 парі немає. | D21: 25 груп із 25. | E21: Закодувати як закріплене правило.
A22: 19 | B22: Інфо | C22: Групових вікон майже немає: 1 випадок на 125 групо-днів у кожному тижні (гр. 93, чт: пари 1, 2, 4). | D22: Група 93, четвер. | E22: Штраф за вікна в генераторі великий.
A23: 20 | B23: Інфо | C23: Дзвінки в БД збігаються з графіком освітнього процесу: 09:00–10:20, 10:40–12:00, 12:30–13:50, 14:00–15:20. | D23: bell_schedule: 4 записи. | E23: Змін не потрібно.

Sheet Навантаження
A1: Група | B1: Курс | C1: Предмет | D1: Викладач | E1: 2-й викладач | F1: Пар (чисельник) | G1: Пар (знаменник) | H1: Пар за 2 тижні | I1: Години на семестр (з плану) | J1: Розрахункові години за розкладом | K1: Різниця (план − розклад) | L1: Примітка
A2: 75 | B2: =IFERROR(VLOOKUP(A2,Групи!$A$2:$E$26,5,FALSE()),"") -> 4 | C2: Іноземна мова (за професійним спрямуванням) | D2: Токарєва О.В. | F2: 1 | G2: 1 | H2: =F2+G2 -> 2 | J2: =IF(B2="","",Параметри!$B$4*(F2*INDEX(Параметри!$C$9:$C$12,B2)+G2*INDEX(Параметри!$D$9:$D$12,B2))) -> 40 | K2: =IF(OR(I2="",J2=""),"",I2-J2)
A3: 75 | B3: =IFERROR(VLOOKUP(A3,Групи!$A$2:$E$26,5,FALSE()),"") -> 4 | C3: Інфокомунікаційні системи та мережі | D3: Буханець В.О. | F3: 3 | G3: 3 | H3: =F3+G3 -> 6 | J3: =IF(B3="","",Параметри!$B$4*(F3*INDEX(Параметри!$C$9:$C$12,B3)+G3*INDEX(Параметри!$D$9:$D$12,B3))) -> 120 | K3: =IF(OR(I3="",J3=""),"",I3-J3)
A4: 75 | B4: =IFERROR(VLOOKUP(A4,Групи!$A$2:$E$26,5,FALSE()),"") -> 4 | C4: Виховна година | D4: Токарєва О.В. | F4: 1 | G4: 1 | H4: =F4+G4 -> 2 | J4: =IF(B4="","",Параметри!$B$4*(F4*INDEX(Параметри!$C$9:$C$12,B4)+G4*INDEX(Параметри!$D$9:$D$12,B4))) -> 40 | K4: =IF(OR(I4="",J4=""),"",I4-J4) | L4: Закріплено: чт, 4 пара, щотижня
A5: 75 | B5: =IFERROR(VLOOKUP(A5,Групи!$A$2:$E$26,5,FALSE()),"") -> 4 | C5: Діагностика та ремонт радіоелектронної апаратури | D5: Рищиковець Т.Т. | F5: 2 | G5: 2 | H5: =F5+G5 -> 4 | J5: =IF(B5="","",Параметри!$B$4*(F5*INDEX(Параметри!$C$9:$C$12,B5)+G5*INDEX(Параметри!$D$9:$D$12,B5))) -> 80 | K5: =IF(OR(I5="",J5=""),"",I5-J5)
A6: 75 | B6: =IFERROR(VLOOKUP(A6,Групи!$A$2:$E$26,5,FALSE()),"") -> 4 | C6: Економіка промисловості, основи підприємництва | D6: Басюк Н.Б. | F6: 2 | G6: 2 | H6: =F6+G6 -> 4 | J6: =IF(B6="","",Параметри!$B$4*(F6*INDEX(Параметри!$C$9:$C$12,B6)+G6*INDEX(Параметри!$D$9:$D$12,B6))) -> 80 | K6: =IF(OR(I6="",J6=""),"",I6-J6)
A7: 75 | B7: =IFERROR(VLOOKUP(A7,Групи!$A$2:$E$26,5,FALSE()),"") -> 4 | C7: Мікропроцесори та мікроконтролери | D7: Криволап В.В. | F7: 2 | G7: 2 | H7: =F7+G7 -> 4 | J7: =IF(B7="","",Параметри!$B$4*(F7*INDEX(Параметри!$C$9:$C$12,B7)+G7*INDEX(Параметри!$D$9:$D$12,B7))) -> 80 | K7: =IF(OR(I7="",J7=""),"",I7-J7)
A8: 75 | B8: =IFERROR(VLOOKUP(A8,Групи!$A$2:$E$26,5,FALSE()),"") -> 4 | C8: Процеси зберігання та захисту інформації | D8: Криволап В.В. | F8: 2 | G8: 3 | H8: =F8+G8 -> 5 | J8: =IF(B8="","",Параметри!$B$4*(F8*INDEX(Параметри!$C$9:$C$12,B8)+G8*INDEX(Параметри!$D$9:$D$12,B8))) -> 100 | K8: =IF(OR(I8="",J8=""),"",I8-J8)
A9: 75 | B9: =IFERROR(VLOOKUP(A9,Групи!$A$2:$E$26,5,FALSE()),"") -> 4 | C9: Системи автоматичного керування | D9: Миргородський Д.А. | F9: 3 | G9: 2 | H9: =F9+G9 -> 5 | J9: =IF(B9="","",Параметри!$B$4*(F9*INDEX(Параметри!$C$9:$C$12,B9)+G9*INDEX(Параметри!$D$9:$D$12,B9))) -> 100 | K9: =IF(OR(I9="",J9=""),"",I9-J9)
A10: 75 | B10: =IFERROR(VLOOKUP(A10,Групи!$A$2:$E$26,5,FALSE()),"") -> 4 | C10: Фізичне виховання | D10: Шапошнікова О.І. | F10: 1 | G10: 1 | H10: =F10+G10 -> 2 | J10: =IF(B10="","",Параметри!$B$4*(F10*INDEX(Параметри!$C$9:$C$12,B10)+G10*INDEX(Параметри!$D$9:$D$12,B10))) -> 40 | K10: =IF(OR(I10="",J10=""),"",I10-J10)
A11: 76 | B11: =IFERROR(VLOOKUP(A11,Групи!$A$2:$E$26,5,FALSE()),"") -> 4 | C11: Іноземна мова (за професійним спрямуванням) | D11: Гребенюк А.А. | F11: 1 | G11: 1 | H11: =F11+G11 -> 2 | J11: =IF(B11="","",Параметри!$B$4*(F11*INDEX(Параметри!$C$9:$C$12,B11)+G11*INDEX(Параметри!$D$9:$D$12,B11))) -> 40 | K11: =IF(OR(I11="",J11=""),"",I11-J11)
A12: 76 | B12: =IFERROR(VLOOKUP(A12,Групи!$A$2:$E$26,5,FALSE()),"") -> 4 | C12: Інфокомунікаційні системи та мережі | D12: Буханець В.О. | F12: 3 | G12: 3 | H12: =F12+G12 -> 6 | J12: =IF(B12="","",Параметри!$B$4*(F12*INDEX(Параметри!$C$9:$C$12,B12)+G12*INDEX(Параметри!$D$9:$D$12,B12))) -> 120 | K12: =IF(OR(I12="",J12=""),"",I12-J12)
A13: 76 | B13: =IFERROR(VLOOKUP(A13,Групи!$A$2:$E$26,5,FALSE()),"") -> 4 | C13: Виховна година | D13: Каліста Ю.В. | F13: 1 | G13: 1 | H13: =F13+G13 -> 2 | J13: =IF(B13="","",Параметри!$B$4*(F13*INDEX(Параметри!$C$9:$C$12,B13)+G13*INDEX(Параметри!$D$9:$D$12,B13))) -> 40 | K13: =IF(OR(I13="",J13=""),"",I13-J13) | L13: Закріплено: чт, 4 пара, щотижня
A14: 76 | B14: =IFERROR(VLOOKUP(A14,Групи!$A$2:$E$26,5,FALSE()),"") -> 4 | C14: Діагностика та ремонт радіоелектронної апаратури | D14: Рищиковець Т.Т. | F14: 2 | G14: 2 | H14: =F14+G14 -> 4 | J14: =IF(B14="","",Параметри!$B$4*(F14*INDEX(Параметри!$C$9:$C$12,B14)+G14*INDEX(Параметри!$D$9:$D$12,B14))) -> 80 | K14: =IF(OR(I14="",J14=""),"",I14-J14)
A15: 76 | B15: =IFERROR(VLOOKUP(A15,Групи!$A$2:$E$26,5,FALSE()),"") -> 4 | C15: Економіка промисловості, основи підприємництва | D15: Басюк Н.Б. | F15: 2 | G15: 2 | H15: =F15+G15 -> 4 | J15: =IF(B15="","",Параметри!$B$4*(F15*INDEX(Параметри!$C$9:$C$12,B15)+G15*INDEX(Параметри!$D$9:$D$12,B15))) -> 80 | K15: =IF(OR(I15="",J15=""),"",I15-J15)
A16: 76 | B16: =IFERROR(VLOOKUP(A16,Групи!$A$2:$E$26,5,FALSE()),"") -> 4 | C16: Мікропроцесори та мікроконтролери | D16: Криволап В.В. | F16: 2 | G16: 2 | H16: =F16+G16 -> 4 | J16: =IF(B16="","",Параметри!$B$4*(F16*INDEX(Параметри!$C$9:$C$12,B16)+G16*INDEX(Параметри!$D$9:$D$12,B16))) -> 80 | K16: =IF(OR(I16="",J16=""),"",I16-J16)
A17: 76 | B17: =IFERROR(VLOOKUP(A17,Групи!$A$2:$E$26,5,FALSE()),"") -> 4 | C17: Процеси зберігання та захисту інформації | D17: Криволап В.В. | F17: 2 | G17: 3 | H17: =F17+G17 -> 5 | J17: =IF(B17="","",Параметри!$B$4*(F17*INDEX(Параметри!$C$9:$C$12,B17)+G17*INDEX(Параметри!$D$9:$D$12,B17))) -> 100 | K17: =IF(OR(I17="",J17=""),"",I17-J17)
A18: 76 | B18: =IFERROR(VLOOKUP(A18,Групи!$A$2:$E$26,5,FALSE()),"") -> 4 | C18: Системи автоматичного керування | D18: Миргородський Д.А. | F18: 3 | G18: 2 | H18: =F18+G18 -> 5 | J18: =IF(B18="","",Параметри!$B$4*(F18*INDEX(Параметри!$C$9:$C$12,B18)+G18*INDEX(Параметри!$D$9:$D$12,B18))) -> 100 | K18: =IF(OR(I18="",J18=""),"",I18-J18)
A19: 76 | B19: =IFERROR(VLOOKUP(A19,Групи!$A$2:$E$26,5,FALSE()),"") -> 4 | C19: Фізичне виховання | D19: Шапошнікова О.І. | F19: 1 | G19: 1 | H19: =F19+G19 -> 2 | J19: =IF(B19="","",Параметри!$B$4*(F19*INDEX(Параметри!$C$9:$C$12,B19)+G19*INDEX(Параметри!$D$9:$D$12,B19))) -> 40 | K19: =IF(OR(I19="",J19=""),"",I19-J19)
A20: 77 | B20: =IFERROR(VLOOKUP(A20,Групи!$A$2:$E$26,5,FALSE()),"") -> 4 | C20: Іноземна мова (за професійним спрямуванням) | D20: Токарєва О.В. | F20: 1 | G20: 1 | H20: =F20+G20 -> 2 | J20: =IF(B20="","",Параметри!$B$4*(F20*INDEX(Параметри!$C$9:$C$12,B20)+G20*INDEX(Параметри!$D$9:$D$12,B20))) -> 40 | K20: =IF(OR(I20="",J20=""),"",I20-J20)
A21: 77 | B21: =IFERROR(VLOOKUP(A21,Групи!$A$2:$E$26,5,FALSE()),"") -> 4 | C21: Інфокомунікаційні системи та мережі | D21: Буханець В.О. | F21: 4 | G21: 4 | H21: =F21+G21 -> 8 | J21: =IF(B21="","",Параметри!$B$4*(F21*INDEX(Параметри!$C$9:$C$12,B21)+G21*INDEX(Параметри!$D$9:$D$12,B21))) -> 160 | K21: =IF(OR(I21="",J21=""),"",I21-J21)
A22: 77 | B22: =IFERROR(VLOOKUP(A22,Групи!$A$2:$E$26,5,FALSE()),"") -> 4 | C22: Автоматизовані системи | D22: Прохоркіна Н.Ю. | F22: 2 | G22: 2 | H22: =F22+G22 -> 4 | J22: =IF(B22="","",Параметри!$B$4*(F22*INDEX(Параметри!$C$9:$C$12,B22)+G22*INDEX(Параметри!$D$9:$D$12,B22))) -> 80 | K22: =IF(OR(I22="",J22=""),"",I22-J22)
A23: 77 | B23: =IFERROR(VLOOKUP(A23,Групи!$A$2:$E$26,5,FALSE()),"") -> 4 | C23: Виховна година | D23: Дишук Л.Г. | F23: 1 | G23: 1 | H23: =F23+G23 -> 2 | J23: =IF(B23="","",Параметри!$B$4*(F23*INDEX(Параметри!$C$9:$C$12,B23)+G23*INDEX(Параметри!$D$9:$D$12,B23))) -> 40 | K23: =IF(OR(I23="",J23=""),"",I23-J23) | L23: Закріплено: чт, 4 пара, щотижня
A24: 77 | B24: =IFERROR(VLOOKUP(A24,Групи!$A$2:$E$26,5,FALSE()),"") -> 4 | C24: Економіка та організація виробництва | D24: Басюк Н.Б. | F24: 2 | G24: 2 | H24: =F24+G24 -> 4 | J24: =IF(B24="","",Параметри!$B$4*(F24*INDEX(Параметри!$C$9:$C$12,B24)+G24*INDEX(Параметри!$D$9:$D$12,B24))) -> 80 | K24: =IF(OR(I24="",J24=""),"",I24-J24)
A25: 77 | B25: =IFERROR(VLOOKUP(A25,Групи!$A$2:$E$26,5,FALSE()),"") -> 4 | C25: Технології звукового та телевізійного мовлення | D25: Валявський В.В. | F25: 2 | G25: 2 | H25: =F25+G25 -> 4 | J25: =IF(B25="","",Параметри!$B$4*(F25*INDEX(Параметри!$C$9:$C$12,B25)+G25*INDEX(Параметри!$D$9:$D$12,B25))) -> 80 | K25: =IF(OR(I25="",J25=""),"",I25-J25)
A26: 77 | B26: =IFERROR(VLOOKUP(A26,Групи!$A$2:$E$26,5,FALSE()),"") -> 4 | C26: Технічне обслуговування та ремонт радіоелектронної апаратури | D26: Васильченко І.А. | F26: 2 | G26: 2 | H26: =F26+G26 -> 4 | J26: =IF(B26="","",Параметри!$B$4*(F26*INDEX(Параметри!$C$9:$C$12,B26)+G26*INDEX(Параметри!$D$9:$D$12,B26))) -> 80 | K26: =IF(OR(I26="",J26=""),"",I26-J26)
A27: 77 | B27: =IFERROR(VLOOKUP(A27,Групи!$A$2:$E$26,5,FALSE()),"") -> 4 | C27: Фізичне виховання | D27: Шапошнікова О.І. | F27: 1 | G27: 1 | H27: =F27+G27 -> 2 | J27: =IF(B27="","",Параметри!$B$4*(F27*INDEX(Параметри!$C$9:$C$12,B27)+G27*INDEX(Параметри!$D$9:$D$12,B27))) -> 40 | K27: =IF(OR(I27="",J27=""),"",I27-J27)
A28: 77 | B28: =IFERROR(VLOOKUP(A28,Групи!$A$2:$E$26,5,FALSE()),"") -> 4 | C28: Цифрова техніка та мікропроцесори | D28: Дворніченко Н.Ф. | F28: 2 | G28: 2 | H28: =F28+G28 -> 4 | J28: =IF(B28="","",Параметри!$B$4*(F28*INDEX(Параметри!$C$9:$C$12,B28)+G28*INDEX(Параметри!$D$9:$D$12,B28))) -> 80 | K28: =IF(OR(I28="",J28=""),"",I28-J28)
A29: 78 | B29: =IFERROR(VLOOKUP(A29,Групи!$A$2:$E$26,5,FALSE()),"") -> 4 | C29: Іноземна мова (за професійним спрямуванням) | D29: Хочинська О.С. | F29: 1 | G29: 1 | H29: =F29+G29 -> 2 | J29: =IF(B29="","",Параметри!$B$4*(F29*INDEX(Параметри!$C$9:$C$12,B29)+G29*INDEX(Параметри!$D$9:$D$12,B29))) -> 40 | K29: =IF(OR(I29="",J29=""),"",I29-J29)
A30: 78 | B30: =IFERROR(VLOOKUP(A30,Групи!$A$2:$E$26,5,FALSE()),"") -> 4 | C30: Виховна година | D30: Шайтанова О.А. | F30: 1 | G30: 1 | H30: =F30+G30 -> 2 | J30: =IF(B30="","",Параметри!$B$4*(F30*INDEX(Параметри!$C$9:$C$12,B30)+G30*INDEX(Параметри!$D$9:$D$12,B30))) -> 40 | K30: =IF(OR(I30="",J30=""),"",I30-J30) | L30: Закріплено: чт, 4 пара, щотижня
A31: 78 | B31: =IFERROR(VLOOKUP(A31,Групи!$A$2:$E$26,5,FALSE()),"") -> 4 | C31: Економіка промисловості, основи підприємництва | D31: Філімончук А.В. | F31: 2 | G31: 2 | H31: =F31+G31 -> 4 | J31: =IF(B31="","",Параметри!$B$4*(F31*INDEX(Параметри!$C$9:$C$12,B31)+G31*INDEX(Параметри!$D$9:$D$12,B31))) -> 80 | K31: =IF(OR(I31="",J31=""),"",I31-J31)
A32: 78 | B32: =IFERROR(VLOOKUP(A32,Групи!$A$2:$E$26,5,FALSE()),"") -> 4 | C32: Конструювання виробів електронної техніки і системи автоматизованого проектування | D32: Шевченко В.І. | F32: 1 | G32: 2 | H32: =F32+G32 -> 3 | J32: =IF(B32="","",Параметри!$B$4*(F32*INDEX(Параметри!$C$9:$C$12,B32)+G32*INDEX(Параметри!$D$9:$D$12,B32))) -> 60 | K32: =IF(OR(I32="",J32=""),"",I32-J32)
A33: 78 | B33: =IFERROR(VLOOKUP(A33,Групи!$A$2:$E$26,5,FALSE()),"") -> 4 | C33: Основи автоматичного керування | D33: Калюжний І.С. | F33: 3 | G33: 3 | H33: =F33+G33 -> 6 | J33: =IF(B33="","",Параметри!$B$4*(F33*INDEX(Параметри!$C$9:$C$12,B33)+G33*INDEX(Параметри!$D$9:$D$12,B33))) -> 120 | K33: =IF(OR(I33="",J33=""),"",I33-J33)
A34: 78 | B34: =IFERROR(VLOOKUP(A34,Групи!$A$2:$E$26,5,FALSE()),"") -> 4 | C34: Процеси зберігання та захисту інформації | D34: Криволап В.В. | F34: 1 | G34: 2 | H34: =F34+G34 -> 3 | J34: =IF(B34="","",Параметри!$B$4*(F34*INDEX(Параметри!$C$9:$C$12,B34)+G34*INDEX(Параметри!$D$9:$D$12,B34))) -> 60 | K34: =IF(OR(I34="",J34=""),"",I34-J34)
A35: 78 | B35: =IFERROR(VLOOKUP(A35,Групи!$A$2:$E$26,5,FALSE()),"") -> 4 | C35: Радіоавтоматика та джерела живлення | D35: Калюжний І.С. | F35: 3 | G35: 1 | H35: =F35+G35 -> 4 | J35: =IF(B35="","",Параметри!$B$4*(F35*INDEX(Параметри!$C$9:$C$12,B35)+G35*INDEX(Параметри!$D$9:$D$12,B35))) -> 80 | K35: =IF(OR(I35="",J35=""),"",I35-J35)
A36: 78 | B36: =IFERROR(VLOOKUP(A36,Групи!$A$2:$E$26,5,FALSE()),"") -> 4 | C36: Технічне обслуговування, ремонт та регулювання побутових електронних та радіотехнічних | D36: Васильченко І.А. | F36: 4 | G36: 4 | H36: =F36+G36 -> 8 | J36: =IF(B36="","",Параметри!$B$4*(F36*INDEX(Параметри!$C$9:$C$12,B36)+G36*INDEX(Параметри!$D$9:$D$12,B36))) -> 160 | K36: =IF(OR(I36="",J36=""),"",I36-J36)
A37: 78 | B37: =IFERROR(VLOOKUP(A37,Групи!$A$2:$E$26,5,FALSE()),"") -> 4 | C37: Фізичне виховання | D37: Шарапова С.П. | F37: 1 | G37: 1 | H37: =F37+G37 -> 2 | J37: =IF(B37="","",Параметри!$B$4*(F37*INDEX(Параметри!$C$9:$C$12,B37)+G37*INDEX(Параметри!$D$9:$D$12,B37))) -> 40 | K37: =IF(OR(I37="",J37=""),"",I37-J37)
A38: 79 | B38: =IFERROR(VLOOKUP(A38,Групи!$A$2:$E$26,5,FALSE()),"") -> 4 | C38: Іноземна мова (за професійним спрямуванням) | D38: Токарєва О.В. | E38: Гребенюк А.А. | F38: 1 | G38: 1 | H38: =F38+G38 -> 2 | J38: =IF(B38="","",Параметри!$B$4*(F38*INDEX(Параметри!$C$9:$C$12,B38)+G38*INDEX(Параметри!$D$9:$D$12,B38))) -> 40 | K38: =IF(OR(I38="",J38=""),"",I38-J38) | L38: Підгрупи: 2 викладачі в одну пару
A39: 79 | B39: =IFERROR(VLOOKUP(A39,Групи!$A$2:$E$26,5,FALSE()),"") -> 4 | C39: Виховна година | D39: Домніна Г.С. | F39: 1 | G39: 1 | H39: =F39+G39 -> 2 | J39: =IF(B39="","",Параметри!$B$4*(F39*INDEX(Параметри!$C$9:$C$12,B39)+G39*INDEX(Параметри!$D$9:$D$12,B39))) -> 40 | K39: =IF(OR(I39="",J39=""),"",I39-J39) | L39: Закріплено: чт, 4 пара, щотижня
A40: 79 | B40: =IFERROR(VLOOKUP(A40,Групи!$A$2:$E$26,5,FALSE()),"") -> 4 | C40: Відеоінформаційні технології | D40: Чорний О.А. | F40: 3 | G40: 2 | H40: =F40+G40 -> 5 | J40: =IF(B40="","",Параметри!$B$4*(F40*INDEX(Параметри!$C$9:$C$12,B40)+G40*INDEX(Параметри!$D$9:$D$12,B40))) -> 100 | K40: =IF(OR(I40="",J40=""),"",I40-J40)
...

Sheet Групи
A1: Група | B1: Шифр (зі скану) | C1: Спеціальність | D1: Рік вступу | E1: Курс | F1: Тижнів теорії, 1 сем. | G1: Відділення в QuickRaport | H1: faculty_id у БД | I1: Примітка
A2: 75 | B2: ТР-23-1/9-75 | C2: ТР | D2: 2023 | E2: =Параметри!$B$5-D2+1 -> 4 | F2: =INDEX(Параметри!$B$9:$B$12,E2) -> 20 | G2: ІТ | H2: 13
A3: 76 | B3: ТР-23-2/9-76 | C3: ТР | D3: 2023 | E3: =Параметри!$B$5-D3+1 -> 4 | F3: =INDEX(Параметри!$B$9:$B$12,E3) -> 20 | G3: ІТ | H3: 13
A4: 77 | B4: РЗ-23-1/9-77 | C4: РЗ | D4: 2023 | E4: =Параметри!$B$5-D4+1 -> 4 | F4: =INDEX(Параметри!$B$9:$B$12,E4) -> 20 | G4: РЗ | H4: 13
A5: 78 | B5: ЕА-23-1/9-78 | C5: ЕА | D5: 2023 | E5: =Параметри!$B$5-D5+1 -> 4 | F5: =INDEX(Параметри!$B$9:$B$12,E5) -> 20 | G5: РЗ | H5: 13
A6: 79 | B6: КІ-23-1/9-79 | C6: КІ | D6: 2023 | E6: =Параметри!$B$5-D6+1 -> 4 | F6: =INDEX(Параметри!$B$9:$B$12,E6) -> 20 | G6: КІ | H6: 15
A7: 80 | B7: КІ-23-2/9-80 | C7: КІ | D7: 2023 | E7: =Параметри!$B$5-D7+1 -> 4 | F7: =INDEX(Параметри!$B$9:$B$12,E7) -> 20 | G7: КІ | H7: 15
A8: 81 | B8: ТР-24-1/9-81 | C8: ТР | D8: 2024 | E8: =Параметри!$B$5-D8+1 -> 3 | F8: =INDEX(Параметри!$B$9:$B$12,E8) -> 17 | G8: ІТ | H8: 12
A9: 82 | B9: ТР-24-2/9-82 | C9: ТР | D9: 2024 | E9: =Параметри!$B$5-D9+1 -> 3 | F9: =INDEX(Параметри!$B$9:$B$12,E9) -> 17 | G9: ІТ | H9: 12
A10: 83 | B10: РЗ-24-1/9-83 | C10: РЗ | D10: 2024 | E10: =Параметри!$B$5-D10+1 -> 3 | F10: =INDEX(Параметри!$B$9:$B$12,E10) -> 17 | G10: РЗ | H10: 13
A11: 84 | B11: ЕА-24-1/9-84 | C11: ЕА | D11: 2024 | E11: =Параметри!$B$5-D11+1 -> 3 | F11: =INDEX(Параметри!$B$9:$B$12,E11) -> 17 | G11: РЗ | H11: 13
A12: 85 | B12: КІ-24-1/9-85 | C12: КІ | D12: 2024 | E12: =Параметри!$B$5-D12+1 -> 3 | F12: =INDEX(Параметри!$B$9:$B$12,E12) -> 17 | G12: КІ | H12: 15
A13: 86 | B13: КІ-24-2/9-86 | C13: КІ | D13: 2024 | E13: =Параметри!$B$5-D13+1 -> 3 | F13: =INDEX(Параметри!$B$9:$B$12,E13) -> 17 | G13: КІ | H13: 15
A14: 87 | B14: ТР-25-1/9-87 | C14: ТР | D14: 2025 | E14: =Параметри!$B$5-D14+1 -> 2 | F14: =INDEX(Параметри!$B$9:$B$12,E14) -> 17 | G14: ІТ | H14: 13 | I14: Блок «Захист України» (пн, 4 пари, чисельник)
A15: 88 | B15: ЕА-25-1/9-88 | C15: ЕА | D15: 2025 | E15: =Параметри!$B$5-D15+1 -> 2 | F15: =INDEX(Параметри!$B$9:$B$12,E15) -> 17 | G15: РЗ | H15: 12 | I15: Другий курс, але блоку «Захист України» у розкладі немає
A16: 89 | B16: ЕА-25-2/9-89 | C16: ЕА | D16: 2025 | E16: =Параметри!$B$5-D16+1 -> 2 | F16: =INDEX(Параметри!$B$9:$B$12,E16) -> 17 | G16: РЗ | H16: 12 | I16: Блок «Захист України» (пн, 4 пари, чисельник)
A17: 90 | B17: КІ-25-1/9-90 | C17: КІ | D17: 2025 | E17: =Параметри!$B$5-D17+1 -> 2 | F17: =INDEX(Параметри!$B$9:$B$12,E17) -> 17 | G17: КІ | H17: 15 | I17: Блок «Захист України» (пн, 4 пари, чисельник)
A18: 91 | B18: КІ-25-2/9-91 | C18: КІ | D18: 2025 | E18: =Параметри!$B$5-D18+1 -> 2 | F18: =INDEX(Параметри!$B$9:$B$12,E18) -> 17 | G18: КІ | H18: 15 | I18: Блок «Захист України» (пн, 4 пари, чисельник)
A19: 92 | B19: МЗ-26-92 | C19: МЗ | D19: 2026 | E19: =Параметри!$B$5-D19+1 -> 1 | F19: =INDEX(Параметри!$B$9:$B$12,E19) -> 17 | H19: 11
A20: 93 | B20: МЗ-26-93 | C20: МЗ | D20: 2026 | E20: =Параметри!$B$5-D20+1 -> 1 | F20: =INDEX(Параметри!$B$9:$B$12,E20) -> 17 | H20: 11
A21: 94 | B21: ЕА-26-94 | C21: ЕА | D21: 2026 | E21: =Параметри!$B$5-D21+1 -> 1 | F21: =INDEX(Параметри!$B$9:$B$12,E21) -> 17 | H21: 12
A22: 95 | B22: ЕА-26-95 | C22: ЕА | D22: 2026 | E22: =Параметри!$B$5-D22+1 -> 1 | F22: =INDEX(Параметри!$B$9:$B$12,E22) -> 17 | H22: 12
A23: 96 | B23: КС-26-96 | C23: КС | D23: 2026 | E23: =Параметри!$B$5-D23+1 -> 1 | F23: =INDEX(Параметри!$B$9:$B$12,E23) -> 17 | H23: 14
A24: 97 | B24: КІ-26-97 | C24: КІ | D24: 2026 | E24: =Параметри!$B$5-D24+1 -> 1 | F24: =INDEX(Параметри!$B$9:$B$12,E24) -> 17 | H24: 15
A25: 98 | B25: КІ-26-98 | C25: КІ | D25: 2026 | E25: =Параметри!$B$5-D25+1 -> 1 | F25: =INDEX(Параметри!$B$9:$B$12,E25) -> 17 | H25: 15
A26: 99 | B26: G5-26-99 | C26: G5 | D26: 2026 | E26: =Параметри!$B$5-D26+1 -> 1 | F26: =INDEX(Параметри!$B$9:$B$12,E26) -> 17 | H26: 12 | I26: Перший курс, але сесія в січні (як у 3 курсу). Шифр «G5» прочитано зі скану, перевір.

Sheet Викладачі
A1: Викладач | B1: Аудиторія | C1: Куратор груп | D1: Пар (чисельник) | E1: Пар (знаменник) | F1: Макс. пар на тиждень | G1: Завантаженість слотів | H1: Днів у тижні | I1: Примітка
A2: Домніна Г.С. | B2: 207 | C2: 79 | D2: 16 | E2: 17 | F2: =MAX(D2,E2) -> 17 | G2: =F2/Параметри!$B$3 -> 0.85 | H2: 5
A3: Сесь О.В. | B3: 416 | C3: 84 | D3: 16 | E3: 17 | F3: =MAX(D3,E3) -> 17 | G3: =F3/Параметри!$B$3 -> 0.85 | H3: 5
A4: Дишук Л.Г. | B4: 227 | C4: 77 | D4: 16 | E4: 14 | F4: =MAX(D4,E4) -> 16 | G4: =F4/Параметри!$B$3 -> 0.8 | H4: 5
A5: Каліста Ю.В. | B5: 418 | C5: 76 | D5: 15 | E5: 16 | F5: =MAX(D5,E5) -> 16 | G5: =F5/Параметри!$B$3 -> 0.8 | H5: 5
A6: Прощенко І.М. | B6: 411 | C6: 85 | D6: 13 | E6: 16 | F6: =MAX(D6,E6) -> 16 | G6: =F6/Параметри!$B$3 -> 0.8 | H6: 5
A7: Чорний О.А. | B7: 317 | D7: 16 | E7: 13 | F7: =MAX(D7,E7) -> 16 | G7: =F7/Параметри!$B$3 -> 0.8 | H7: 5
A8: Шапошнікова О.І. | B8: Спортивний комплекс | C8: 95 | D8: 16 | E8: 15 | F8: =MAX(D8,E8) -> 16 | G8: =F8/Параметри!$B$3 -> 0.8 | H8: 5
A9: Юшин П.Б. | B9: 203 | C9: 87 | D9: 15 | E9: 16 | F9: =MAX(D9,E9) -> 16 | G9: =F9/Параметри!$B$3 -> 0.8 | H9: 5 | I9: Спільна аудиторія з 2 інш.
A10: Кондратова О.О. | B10: 425 | C10: 92 | D10: 15 | E10: 14 | F10: =MAX(D10,E10) -> 15 | G10: =F10/Параметри!$B$3 -> 0.75 | H10: 5
A11: Андрєєв В.О. | B11: 203 | D11: 11 | E11: 13 | F11: =MAX(D11,E11) -> 13 | G11: =F11/Параметри!$B$3 -> 0.65 | H11: 5 | I11: Спільна аудиторія з 2 інш.
A12: Басюк Н.Б. | B12: 201 | C12: 81 | D12: 13 | E12: 13 | F12: =MAX(D12,E12) -> 13 | G12: =F12/Параметри!$B$3 -> 0.65 | H12: 4
A13: Грабовчак Т.В. | B13: 212 | C13: 80 | D13: 13 | E13: 12 | F13: =MAX(D13,E13) -> 13 | G13: =F13/Параметри!$B$3 -> 0.65 | H13: 4
A14: Ковальчук-Жук І.О. | B14: 407 | C14: 91 | D14: 12 | E14: 13 | F14: =MAX(D14,E14) -> 13 | G14: =F14/Параметри!$B$3 -> 0.65 | H14: 4
A15: Махинько С.В. | B15: 423 | C15: 90 | D15: 12 | E15: 13 | F15: =MAX(D15,E15) -> 13 | G15: =F15/Параметри!$B$3 -> 0.65 | H15: 4
A16: Хочинська О.С. | B16: 408 | C16: 98 | D16: 13 | E16: 12 | F16: =MAX(D16,E16) -> 13 | G16: =F16/Параметри!$B$3 -> 0.65 | H16: 4
A17: Гребенюк А.А. | B17: 413 | C17: 97 | D17: 12 | E17: 11 | F17: =MAX(D17,E17) -> 12 | G17: =F17/Параметри!$B$3 -> 0.6 | H17: 3
A18: Криволап В.В. | B18: 414 | D18: 9 | E18: 12 | F18: =MAX(D18,E18) -> 12 | G18: =F18/Параметри!$B$3 -> 0.6 | H18: 4
A19: Філіппов Д.В. | B19: Спортивний комплекс | D19: 12 | E19: 10 | F19: =MAX(D19,E19) -> 12 | G19: =F19/Параметри!$B$3 -> 0.6 | H19: 3
A20: Шевченко В.І. | B20: 308 | C20: 88 | D20: 11 | E20: 12 | F20: =MAX(D20,E20) -> 12 | G20: =F20/Параметри!$B$3 -> 0.6 | H20: 4 | I20: Спільна аудиторія з 3 інш.
A21: Токарєва О.В. | B21: 419 | C21: 75 | D21: 11 | E21: 11 | F21: =MAX(D21,E21) -> 11 | G21: =F21/Параметри!$B$3 -> 0.55 | H21: 3
A22: Буханець В.О. | B22: 206 | D22: 10 | E22: 10 | F22: =MAX(D22,E22) -> 10 | G22: =F22/Параметри!$B$3 -> 0.5 | H22: 5
A23: Гончаров О.М. | B23: 426 | C23: 86, 93 | D23: 10 | E23: 10 | F23: =MAX(D23,E23) -> 10 | G23: =F23/Параметри!$B$3 -> 0.5 | H23: 4 | I23: Спільна аудиторія з 1 інш.
A24: Медведєва Л.С. | B24: 229 | C24: 83 | D24: 10 | E24: 10 | F24: =MAX(D24,E24) -> 10 | G24: =F24/Параметри!$B$3 -> 0.5 | H24: 3
A25: Коваль І.А. | B25: 426 | D25: 9 | E25: 7 | F25: =MAX(D25,E25) -> 9 | G25: =F25/Параметри!$B$3 -> 0.45 | H25: 3 | I25: Спільна аудиторія з 1 інш.
A26: Дворніченко Н.Ф. | B26: 303 | C26: 99 | D26: 8 | E26: 8 | F26: =MAX(D26,E26) -> 8 | G26: =F26/Параметри!$B$3 -> 0.4 | H26: 4
A27: Карпова Л.М. | B27: 421 | C27: 94 | D27: 7 | E27: 8 | F27: =MAX(D27,E27) -> 8 | G27: =F27/Параметри!$B$3 -> 0.4 | H27: 4
A28: Прохоркіна Н.Ю. | B28: 301 | D28: 7 | E28: 8 | F28: =MAX(D28,E28) -> 8 | G28: =F28/Параметри!$B$3 -> 0.4 | H28: 4 | I28: Спільна аудиторія з 1 інш.
A29: Бурліков Ю.В. | B29: 308 | D29: 5 | E29: 7 | F29: =MAX(D29,E29) -> 7 | G29: =F29/Параметри!$B$3 -> 0.35 | H29: 5 | I29: Спільна аудиторія з 3 інш.
A30: Валявський В.В. | B30: 310 | D30: 6 | E30: 7 | F30: =MAX(D30,E30) -> 7 | G30: =F30/Параметри!$B$3 -> 0.35 | H30: 4
A31: Філімончук А.В. | B31: 309 | D31: 7 | E31: 7 | F31: =MAX(D31,E31) -> 7 | G31: =F31/Параметри!$B$3 -> 0.35 | H31: 4
A32: Шарапова С.П. | B32: Спортивний комплекс | D32: 5 | E32: 7 | F32: =MAX(D32,E32) -> 7 | G32: =F32/Параметри!$B$3 -> 0.35 | H32: 3
A33: Васильченко І.І. | B33: 209 | D33: 4 | E33: 6 | F33: =MAX(D33,E33) -> 6 | G33: =F33/Параметри!$B$3 -> 0.3 | H33: 3 | I33: Спільна аудиторія з 1 інш.
A34: Васильченко І.А. | B34: 313 | D34: 6 | E34: 6 | F34: =MAX(D34,E34) -> 6 | G34: =F34/Параметри!$B$3 -> 0.3 | H34: 4
A35: Дворніченко А.С. | B35: 405 | D35: 4 | E35: 6 | F35: =MAX(D35,E35) -> 6 | G35: =F35/Параметри!$B$3 -> 0.3 | H35: 3 | I35: Спільна аудиторія з 1 інш.
A36: Калюжний І.С. | B36: 308 | D36: 6 | E36: 4 | F36: =MAX(D36,E36) -> 6 | G36: =F36/Параметри!$B$3 -> 0.3 | H36: 4 | I36: Спільна аудиторія з 3 інш.
A37: Миргородський Д.А. | B37: 308 | D37: 6 | E37: 6 | F37: =MAX(D37,E37) -> 6 | G37: =F37/Параметри!$B$3 -> 0.3 | H37: 4 | I37: Спільна аудиторія з 3 інш.
A38: Правда А.А. | B38: 307 | C38: 96 | D38: 6 | E38: 6 | F38: =MAX(D38,E38) -> 6 | G38: =F38/Параметри!$B$3 -> 0.3 | H38: 5
A39: Продан О.В. | B39: 318 | D39: 5 | E39: 6 | F39: =MAX(D39,E39) -> 6 | G39: =F39/Параметри!$B$3 -> 0.3 | H39: 3
A40: Шайтанова О.А. | B40: 301 | C40: 78 | D40: 6 | E40: 6 | F40: =MAX(D40,E40) -> 6 | G40: =F40/Параметри!$B$3 -> 0.3 | H40: 2 | I40: Спільна аудиторія з 1 інш.
...

Sheet Збіги аудиторій
A1: Аудиторія | B1: День | C1: Пара | D1: Тиждень | E1: Група A | F1: Викладач A | G1: Предмет A | H1: Група B | I1: Викладач B | J1: Предмет B
A2: 203 | B2: Пн | C2: 2 | D2: знаменник | E2: 82 | F2: Андрєєв В.О. | G2: Основи філософських знань (філософія та релігієзнавство), соціологія | H2: 92 | I2: Юшин П.Б. | J2: Всесвітня історія
A3: 203 | B3: Пн | C3: 3 | D3: знаменник | E3: 95 | F3: Андрєєв В.О. | G3: Географія | H3: 88 | I3: Юшин П.Б. | J3: Історія України*
A4: 203 | B4: Вт | C4: 1 | D4: знаменник | E4: 93 | F4: Андрєєв В.О. | G4: Громадянська освіта | H4: 95 | I4: Юшин П.Б. | J4: Всесвітня історія
A5: 203 | B5: Вт | C5: 1 | D5: чисельник | E5: 93 | F5: Андрєєв В.О. | G5: Громадянська освіта | H5: 95 | I5: Юшин П.Б. | J5: Всесвітня історія
A6: 203 | B6: Вт | C6: 2 | D6: знаменник | E6: 94 | F6: Юшин П.Б. | G6: Всесвітня історія | H6: 99 | I6: Андрєєв В.О. | J6: Основи правознавства
A7: 203 | B7: Вт | C7: 2 | D7: чисельник | E7: 94 | F7: Юшин П.Б. | G7: Всесвітня історія | H7: 99 | I7: Андрєєв В.О. | J7: Основи правознавства
A8: 203 | B8: Ср | C8: 3 | D8: знаменник | E8: 79 | F8: Андрєєв В.О. | G8: Економіка промисловості, основи підприємництва | H8: 94 | I8: Кучер М.Д. | J8: Громадянська освіта
A9: 203 | B9: Ср | C9: 3 | D9: знаменник | E9: 79 | F9: Андрєєв В.О. | G9: Економіка промисловості, основи підприємництва | H9: 96 | I9: Юшин П.Б. | J9: Всесвітня історія
A10: 203 | B10: Ср | C10: 3 | D10: знаменник | E10: 94 | F10: Кучер М.Д. | G10: Громадянська освіта | H10: 96 | I10: Юшин П.Б. | J10: Всесвітня історія
A11: 203 | B11: Ср | C11: 3 | D11: чисельник | E11: 79 | F11: Андрєєв В.О. | G11: Економіка та планування виробництва | H11: 94 | I11: Кучер М.Д. | J11: Громадянська освіта
A12: 203 | B12: Ср | C12: 3 | D12: чисельник | E12: 79 | F12: Андрєєв В.О. | G12: Економіка та планування виробництва | H12: 96 | I12: Юшин П.Б. | J12: Всесвітня історія
A13: 203 | B13: Ср | C13: 3 | D13: чисельник | E13: 94 | F13: Кучер М.Д. | G13: Громадянська освіта | H13: 96 | I13: Юшин П.Б. | J13: Всесвітня історія
... A81: 426 | B81: Пт | C81: 3 | D81: чисельник | E81: 91 | F81: Гончаров О.М. | G81: Комп'ютерні технології* | H81: 94 | I81: Коваль І.А. | J81: Математика (Алгебра і початки аналізу)

Sheet Параметри
A1: Параметри та легенда
A3: Слотів на тиждень у викладача | B3: 20 | C3: Припущення: 5 днів × 4 пари.
A4: Годин в одній парі | B4: 2 | C4: Твоє правило: 1 пара = 2 академічні години.
A5: Початок навчального року (рік) | B5: 2026 | C5: Курс групи = цей рік − рік вступу + 1.
A7: Тижні 1-го семестру за графіком освітнього процесу 2026/27
A8: Курс | B8: Тижнів теорії | C8: Чисельник | D8: Знаменник | E8: Що після теорії (за графіком)
A9: 1 | B9: 17 | C9: =ROUNDUP(B9/2,0) -> 9 | D9: =ROUNDDOWN(B9/2,0) -> 8 | E9: Канікули 18–19 тиждень, далі знову теорія. Виняток: група 99, у неї сесія 18–19 і канікули 20–21.
A10: 2 | B10: 17 | C10: =ROUNDUP(B10/2,0) -> 9 | D10: =ROUNDDOWN(B10/2,0) -> 8 | E10: Канікули 18–19 тиждень, далі знову теорія.
A11: 3 | B11: 17 | C11: =ROUNDUP(B11/2,0) -> 9 | D11: =ROUNDDOWN(B11/2,0) -> 8 | E11: Сесія 18–19, канікули 20–21, далі практика за групами.
A12: 4 | B12: 20 | C12: =ROUNDUP(B12/2,0) -> 10 | D12: =ROUNDDOWN(B12/2,0) -> 10 | E12: Теорія до 20-го тижня, сесія 21–22, канікули 23–24, далі практика.
A14: Як користуватися
A15: Аркуш «Навантаження»: пари взято з поточного розкладу. Жовту колонку «Години на семестр (з плану)» заповнюй з навчального плану / аркуша навантаження.
A16: Розрахункові години = 2 × (пар у чисельнику × тижнів чисельника + пар у знаменнику × тижнів знаменника). При 17 тижнях: 9 тижнів чисельника і 8 знаменника, тому «2,5 пари на тиждень» дає рівно 42 пари = 84 год лише як 2 чисельник + 3 знаменник.
A17: Різниця = години з плану − розрахункові за розкладом. Від’ємне число: у розкладі більше годин, ніж у плані.
A18: Аркуш «Групи»: шифр, рік вступу і курс кожної групи (із графіка освітнього процесу 2026/27). Шифри прочитано зі скану, перевір.
A19: Аркуші «Проблеми» і «Збіги аудиторій»: знахідки в даних і твої рішення.
A20: Джерела: дамп бази від 30.09.2026, графік освітнього процесу 2026/27, аркуш навантаження групи 85 (1-й семестр).
